<?xml version="1.0"?>
<robot name="adl200">

  <!-- Base Link -->
  <link name="base_link">
    <visual>
      <geometry>
        <box size="0.65 0.375 0.1"/>
      </geometry>
      <material name="green">
        <color rgba="0.0 1.0 0.0 0.5"/>
      </material>
    </visual>
  </link>

  <!-- Base Footprint -->
  <link name="base_footprint"/>

  <joint name="base_to_base_footprint" type="fixed">
    <parent link="base_footprint"/>
    <child link="base_link"/>
    <origin xyz="0 0 -0.05" rpy="0 0 0"/>
  </joint>

  <!-- Imu -->
  <link name="imu"/>
  
  <joint name="imu_to_base" type="fixed">
    <parent link="base_link"/>
    <child link="imu"/>
    <origin xyz="0 0 0" rpy="0 0 0"/>
  </joint>

  <!-- Wheels -->
  <link name="front_left_wheel">
    <visual>
      <geometry>
        <cylinder radius="0.0825" length="0.07"/>
      </geometry>
      <material name="gray">
        <color rgba="1.0 1.0 1.0 0.8"/>
      </material>
    </visual>
  </link>

  <link name="front_right_wheel">
    <visual>
      <geometry>
        <cylinder radius="0.0825" length="0.07"/>
      </geometry>
      <material name="gray">
        <color rgba="1.0 1.0 1.0 0.8"/>
      </material>
    </visual>
  </link>

  <link name="rear_left_wheel">
    <visual>
      <geometry>
        <cylinder radius="0.0825" length="0.07"/>
      </geometry>
      <material name="gray">
        <color rgba="1.0 1.0 1.0 0.8"/>
      </material>
    </visual>
  </link>

  <link name="rear_right_wheel">
    <visual>
      <geometry>
        <cylinder radius="0.0825" length="0.07"/>
      </geometry>
      <material name="gray">
        <color rgba="1.0 1.0 1.0 0.8"/>
      </material>
    </visual>
  </link>

  <!-- Lidars -->
  <link name="base_scan"/>

  <link name="front_lidar">
    <visual>
      <geometry>
        <cylinder radius="0.03" length="0.05"/>
      </geometry>
      <material name="blue">
        <color rgba="0.0 0.0 1.0 0.5"/>
      </material>
    </visual>
  </link>

  <link name="rear_lidar">
    <visual>
      <geometry>
        <cylinder radius="0.03" length="0.05"/>
      </geometry>
      <material name="blue">
        <color rgba="0.0 0.0 1.0 0.5"/>
      </material>
    </visual>
  </link>

  <!-- Joints for wheels -->
  <joint name="front_left_wheel_joint" type="continuous">
    <parent link="base_link"/>
    <child link="front_left_wheel"/>
    <origin xyz="0.3 0.23 0" rpy="-1.5708 0 0"/>
  </joint>

  <joint name="front_right_wheel_joint" type="continuous">
    <parent link="base_link"/>
    <child link="front_right_wheel"/>
    <origin xyz="0.3 -0.23 0" rpy="-1.5708 0 0"/>
  </joint>

  <joint name="rear_left_wheel_joint" type="continuous">
    <parent link="base_link"/>
    <child link="rear_left_wheel"/>
    <origin xyz="-0.3 0.23 0" rpy="-1.5708 0 0"/>
  </joint>

  <joint name="rear_right_wheel_joint" type="continuous">
    <parent link="base_link"/>
    <child link="rear_right_wheel"/>
    <origin xyz="-0.3 -0.23 0" rpy="-1.5708 0 0"/>
  </joint>

  <!-- Joints for lidars -->
  <joint name="front_lidar_joint" type="fixed">
    <parent link="base_link"/>
    <child link="front_lidar"/>
    <origin xyz="0.37 -0.18 0.08" rpy="0 0 -0.875398"/>
  </joint>

  <joint name="rear_lidar_joint" type="fixed">
    <parent link="base_link"/>
    <child link="rear_lidar"/>
    <origin xyz="-0.37 0.18 0.08" rpy="0 0 2.25619"/>
  </joint>

  <joint name="base_to_base_scan" type="fixed">
    <parent link="base_link"/>
    <child link="base_scan"/>
    <origin xyz="0 0 0.08" rpy="0 0 0"/>
  </joint>

</robot>
<!-- 
<joint name="front_lidar_joint" type="fixed">
    <parent link="base_link"/>
    <child link="front_lidar"/>
    <origin xyz="0.30 -0.15 0.08" rpy="0 0 0.785398"/>
  </joint>

  <joint name="rear_lidar_joint" type="fixed">
    <parent link="base_link"/>
    <child link="rear_lidar"/>
    <origin xyz="-0.30 0.15 0.08" rpy="0 0 -2.35619"/>
  </joint> -->